File: Specimen_RawData_1.csv
Break (Standard) : Extension at Break (Standard),2.03373,mm

Time,Extension,Load,Tensile strain,Tensile stress,Displacement (Strain 2),Strain 2
(sec),(mm),(N),(mm/mm),(MPa),(mm),(mm/mm)
0.00000,0.00000,26.06470,0.00000,0.26980,0.06139,0.00246
0.06800,0.00080,27.30197,0.00008,0.28261,0.06145,0.00246
0.13600,0.00343,30.55345,0.00034,0.31627,0.06119,0.00245
0.20400,0.00664,34.18816,0.00065,0.35389,0.06133,0.00245
0.27200,0.01012,37.02459,0.00100,0.38325,0.06136,0.00245
0.34000,0.01334,39.99459,0.00131,0.41399,0.06163,0.00247
0.40800,0.01650,42.63856,0.00162,0.44136,0.06171,0.00247
0.47600,0.01961,44.88957,0.00193,0.46466,0.06155,0.00246
0.54400,0.02266,47.24507,0.00223,0.48905,0.06173,0.00247
0.61200,0.02566,49.00829,0.00253,0.50730,0.06146,0.00246
0.68000,0.02845,50.59738,0.00280,0.52375,0.06167,0.00247
0.74800,0.03161,52.61863,0.00311,0.54467,0.06190,0.00248
0.81600,0.03445,54.18703,0.00339,0.56090,0.06187,0.00247
0.88400,0.03729,56.40159,0.00367,0.58383,0.06188,0.00248
0.95200,0.04029,63.41332,0.00397,0.65641,0.06129,0.00245
1.02000,0.04312,70.76551,0.00424,0.73251,0.06114,0.00245
1.08800,0.04602,75.39727,0.00453,0.78046,0.06138,0.00246
1.15600,0.04875,79.69409,0.00480,0.82494,0.06155,0.00246
1.22400,0.05186,83.81299,0.00510,0.86757,0.06184,0.00247
1.29200,0.05464,87.95018,0.00538,0.91040,0.06166,0.00247
1.36000,0.05748,91.74439,0.00566,0.94967,0.06139,0.00246
1.42800,0.06043,95.64621,0.00595,0.99006,0.06124,0.00245
1.49600,0.06332,99.10280,0.00623,1.02584,0.06120,0.00245
1.56400,0.06621,102.37274,0.00652,1.05969,0.06143,0.00246
1.63200,0.06895,105.54008,0.00679,1.09247,0.06139,0.00246
1.70000,0.07205,109.23261,0.00709,1.13070,0.06133,0.00245
1.76800,0.07484,112.36263,0.00737,1.16310,0.06160,0.00246
1.83600,0.07768,115.63062,0.00765,1.19692,0.06171,0.00247
1.90400,0.08057,118.36241,0.00793,1.22520,0.06173,0.00247
1.97200,0.08352,121.72882,0.00822,1.26005,0.06163,0.00247
2.04000,0.08641,124.27703,0.00850,1.28643,0.06148,0.00246
2.10800,0.08909,126.40716,0.00877,1.30847,0.06160,0.00246
2.17600,0.09225,129.29034,0.00908,1.33832,0.06156,0.00246
2.24400,0.09504,131.44245,0.00935,1.36060,0.06155,0.00246
2.31200,0.09787,133.55659,0.00963,1.38248,0.06141,0.00246
2.38000,0.10071,135.28667,0.00991,1.40039,0.06142,0.00246
2.44800,0.10366,137.66889,0.01020,1.42505,0.06155,0.00246
2.51600,0.10650,139.12530,0.01048,1.44012,0.06169,0.00247
2.58400,0.10929,140.71040,0.01076,1.45653,0.06165,0.00247
2.65200,0.11234,142.44824,0.01106,1.47452,0.06160,0.00246
2.72000,0.11518,143.98347,0.01134,1.49041,0.06124,0.00245
2.78800,0.11807,145.28717,0.01162,1.50391,0.06114,0.00245
2.85600,0.12086,146.53272,0.01190,1.51680,0.06134,0.00245
2.92400,0.12386,148.23428,0.01219,1.53441,0.06157,0.00246
2.99200,0.12670,149.46763,0.01247,1.54718,0.06134,0.00245
3.06000,0.12943,150.71608,0.01274,1.56010,0.06144,0.00246
3.12800,0.13248,152.26226,0.01304,1.57611,0.06170,0.00247
3.19600,0.13532,153.87142,0.01332,1.59276,0.06144,0.00246
3.26400,0.13821,155.56252,0.01360,1.61027,0.06145,0.00246
3.33200,0.14095,157.12245,0.01387,1.62642,0.06179,0.00247
3.40000,0.14405,159.12468,0.01418,1.64714,0.06183,0.00247
3.46800,0.14684,160.66682,0.01445,1.66311,0.06135,0.00245
3.53600,0.14962,162.40085,0.01473,1.68106,0.06127,0.00245
3.60400,0.15262,164.74209,0.01502,1.70529,0.06144,0.00246
3.67200,0.15546,166.48744,0.01530,1.72336,0.06145,0.00246
3.74000,0.15836,168.35757,0.01559,1.74271,0.06177,0.00247
3.80800,0.16104,170.04797,0.01585,1.76021,0.06164,0.00247
3.87600,0.16414,172.36568,0.01616,1.78420,0.06149,0.00246
3.94400,0.16698,174.20853,0.01644,1.80328,0.06141,0.00246
4.01200,0.16977,175.99018,0.01671,1.82172,0.06159,0.00246
4.08000,0.17271,178.32020,0.01700,1.84584,0.06144,0.00246
4.14800,0.17561,180.31033,0.01728,1.86644,0.06141,0.00246
4.21600,0.17850,182.41177,0.01757,1.88819,0.06123,0.00245
4.28400,0.18123,184.25412,0.01784,1.90726,0.06136,0.00245
4.35200,0.18429,186.99663,0.01814,1.93565,0.06153,0.00246
4.42000,0.18712,189.19365,0.01842,1.95839,0.06125,0.00245
4.48800,0.18996,191.73705,0.01870,1.98472,0.06142,0.00246
4.55600,0.19286,194.34494,0.01898,2.01172,0.06129,0.00245
4.62400,0.19575,197.43845,0.01927,2.04374,0.06144,0.00246
4.69200,0.19870,200.26841,0.01956,2.07303,0.06147,0.00246
4.76000,0.20137,203.10363,0.01982,2.10238,0.06154,0.00246
4.82800,0.20448,206.79583,0.02013,2.14060,0.06158,0.00246
4.89600,0.20727,210.20700,0.02040,2.17591,0.06153,0.00246
4.96400,0.21016,213.68690,0.02069,2.21193,0.06154,0.00246
5.03200,0.21295,217.19523,0.02096,2.24825,0.06156,0.00246
5.10000,0.21595,221.23331,0.02125,2.29005,0.06144,0.00246
5.16800,0.21879,224.95592,0.02153,2.32858,0.06167,0.00247
5.23600,0.22152,228.84908,0.02180,2.36888,0.06154,0.00246
5.30400,0.22462,233.31136,0.02211,2.41507,0.06155,0.00246
5.37200,0.22741,237.00546,0.02238,2.45331,0.06158,0.00246
5.44000,0.23030,241.50135,0.02267,2.49985,0.06156,0.00246
5.50800,0.23309,245.32515,0.02294,2.53943,0.06180,0.00247
5.57600,0.23614,250.09361,0.02324,2.58879,0.06150,0.00246
5.64400,0.23893,254.31552,0.02352,2.63249,0.06134,0.00245
5.71200,0.24171,259.00712,0.02379,2.68105,0.06119,0.00245
5.78000,0.24477,264.07180,0.02409,2.73348,0.06135,0.00245
5.84800,0.24755,268.32931,0.02437,2.77755,0.06142,0.00246
5.91600,0.25045,273.56163,0.02465,2.83171,0.06137,0.00245
5.98400,0.25323,277.93673,0.02492,2.87700,0.06152,0.00246
6.05200,0.25629,283.63748,0.02522,2.93601,0.06146,0.00246
6.12000,0.25907,287.86208,0.02550,2.97974,0.06125,0.00245
6.18800,0.26191,292.75250,0.02578,3.03036,0.06159,0.00246
6.25600,0.26486,298.16804,0.02607,3.08642,0.06142,0.00246
6.32400,0.26764,303.09406,0.02634,3.13741,0.06149,0.00246
6.39200,0.27059,308.12731,0.02663,3.18951,0.06142,0.00246
6.46000,0.27332,312.71101,0.02690,3.23696,0.06172,0.00247
6.52800,0.27643,318.91429,0.02721,3.30117,0.06155,0.00246
6.59600,0.27927,323.81586,0.02749,3.35191,0.06148,0.00246
6.66400,0.28205,328.78359,0.02776,3.40333,0.06150,0.00246
6.73200,0.28500,334.04700,0.02805,3.45781,0.06165,0.00247
6.80000,0.28789,338.25045,0.02834,3.50132,0.06162,0.00246
6.86800,0.29079,343.38224,0.02862,3.55444,0.06173,0.00247
6.93600,0.29352,348.46933,0.02889,3.60710,0.06169,0.00247
7.00400,0.29662,354.39002,0.02920,3.66839,0.06147,0.00246
7.07200,0.29941,358.17157,0.02947,3.70753,0.06143,0.00246
7.14000,0.30225,363.25428,0.02975,3.76014,0.06133,0.00245
7.20800,0.30514,367.58104,0.03003,3.80493,0.06148,0.00246
7.27600,0.30809,373.13126,0.03032,3.86238,0.06145,0.00246
7.34400,0.31093,377.01817,0.03060,3.90262,0.06140,0.00246
7.41200,0.31366,381.89518,0.03087,3.95310,0.06144,0.00246
7.48000,0.31671,388.02724,0.03117,4.01657,0.06149,0.00246
7.54800,0.31950,392.36393,0.03145,4.06147,0.06154,0.00246
7.61600,0.32239,397.28916,0.03173,4.11245,0.06159,0.00246
7.68400,0.32529,401.86532,0.03202,4.15982,0.06143,0.00246
7.75200,0.32818,407.35773,0.03230,4.21667,0.06147,0.00246
7.82000,0.33107,411.74649,0.03259,4.26210,0.06154,0.00246
7.88800,0.33380,417.16925,0.03285,4.31823,0.06168,0.00247
7.95600,0.33691,422.87903,0.03316,4.37734,0.06177,0.00247
8.02400,0.33970,428.35141,0.03343,4.43398,0.06154,0.00246
8.09200,0.34259,436.14588,0.03372,4.51466,0.06164,0.00247
8.16000,0.34537,443.19218,0.03399,4.58760,0.06167,0.00247
8.22800,0.34837,452.24980,0.03429,4.68136,0.06173,0.00247
8.29600,0.35127,459.59176,0.03457,4.75736,0.06174,0.00247
8.36400,0.35395,467.58416,0.03484,4.84009,0.06141,0.00246
8.43200,0.35705,476.54623,0.03514,4.93286,0.06152,0.00246
8.50000,0.35984,484.03306,0.03542,5.01036,0.06114,0.00245
8.56800,0.36273,493.52841,0.03570,5.10865,0.06158,0.00246
8.63600,0.36552,501.70703,0.03598,5.19331,0.06129,0.00245
8.70400,0.36852,511.53693,0.03627,5.29506,0.06158,0.00246
8.77200,0.37141,518.75185,0.03656,5.36974,0.06162,0.00246
8.84000,0.37414,527.47954,0.03683,5.46008,0.06133,0.00245
8.90800,0.37714,536.73461,0.03712,5.55589,0.06163,0.00247
8.97600,0.37998,545.40748,0.03740,5.64566,0.06134,0.00245
9.04400,0.38287,553.96060,0.03768,5.73420,0.06157,0.00246
9.11200,0.38561,561.59740,0.03795,5.81325,0.06162,0.00246
9.18000,0.38871,571.68541,0.03826,5.91767,0.06114,0.00245
9.24800,0.39155,579.43270,0.03854,5.99786,0.06139,0.00246
9.31600,0.39434,587.99710,0.03881,6.08652,0.06171,0.00247
9.38400,0.39729,596.27540,0.03910,6.17221,0.06166,0.00247
9.45200,0.40018,605.37284,0.03939,6.26638,0.06186,0.00247
9.52000,0.40302,614.20575,0.03967,6.35781,0.06154,0.00246
9.58800,0.40575,622.06121,0.03994,6.43912,0.06146,0.00246
9.65600,0.40886,632.67594,0.04024,6.54900,0.06132,0.00245
9.72400,0.41170,640.90624,0.04052,6.63419,0.06136,0.00245
9.79200,0.41454,649.59498,0.04080,6.72413,0.06180,0.00247
9.86000,0.41743,658.21018,0.04109,6.81331,0.06116,0.00245
9.92800,0.42027,667.39965,0.04136,6.90843,0.06148,0.00246
9.99600,0.42321,675.59559,0.04165,6.99327,0.06163,0.00247
10.06400,0.42589,683.33147,0.04192,7.07335,0.06134,0.00245
10.13200,0.42900,692.50468,0.04222,7.16830,0.06163,0.00247
10.20000,0.43179,700.22542,0.04250,7.24822,0.06122,0.00245
10.26800,0.43468,708.49260,0.04278,7.33380,0.06138,0.00246
10.33600,0.43752,715.30005,0.04306,7.40426,0.06176,0.00247
10.40400,0.44046,723.82266,0.04335,7.49248,0.06167,0.00247
10.47200,0.44336,730.96421,0.04364,7.56641,0.06189,0.00248
10.54000,0.44604,738.11956,0.04390,7.64048,0.06132,0.00245
10.60800,0.44914,746.74459,0.04421,7.72976,0.06140,0.00246
10.67600,0.45193,754.23170,0.04448,7.80726,0.06168,0.00247
10.74400,0.45482,761.85990,0.04477,7.88622,0.06127,0.00245
10.81200,0.45766,769.36925,0.04505,7.96395,0.06188,0.00248
10.88000,0.46066,779.09868,0.04534,8.06466,0.06151,0.00246
10.94800,0.46350,786.72571,0.04562,8.14361,0.06143,0.00246
11.01600,0.46629,794.98557,0.04589,8.22911,0.06179,0.00247
11.08400,0.46934,803.65626,0.04619,8.31886,0.06122,0.00245
11.15200,0.47207,812.30694,0.04646,8.40841,0.06126,0.00245
11.22000,0.47502,821.46250,0.04675,8.50318,0.06122,0.00245
11.28800,0.47780,829.68034,0.04703,8.58825,0.06125,0.00245
11.35600,0.48080,840.62995,0.04732,8.70159,0.06174,0.00247
11.42400,0.48364,850.16895,0.04760,8.80033,0.06137,0.00245
11.49200,0.48643,861.36036,0.04788,8.91617,0.06149,0.00246
11.56000,0.48943,873.01103,0.04817,9.03677,0.06157,0.00246
11.62800,0.49227,886.36927,0.04845,9.17505,0.06158,0.00246
11.69600,0.49516,899.15631,0.04874,9.30741,0.06206,0.00248
11.76400,0.49789,911.15054,0.04901,9.43157,0.06144,0.00246
11.83200,0.50100,925.91068,0.04931,9.58435,0.06125,0.00245
11.90000,0.50379,938.19771,0.04959,9.71154,0.06146,0.00246
11.96800,0.50657,951.81294,0.04986,9.85247,0.06113,0.00245
12.03600,0.50957,964.55310,0.05015,9.98435,0.06170,0.00247
12.10400,0.51241,979.20589,0.05043,10.13602,0.06195,0.00248
12.17200,0.51530,992.37610,0.05072,10.27235,0.06167,0.00247
12.24000,0.51804,1005.38224,0.05099,10.40698,0.06178,0.00247
12.30800,0.52114,1020.68737,0.05129,10.56541,0.06154,0.00246
12.37600,0.52393,1033.51090,0.05157,10.69815,0.06132,0.00245
12.44400,0.52677,1047.13853,0.05185,10.83921,0.06114,0.00245
12.51200,0.52966,1060.27376,0.05213,10.97518,0.06125,0.00245
12.58000,0.53255,1076.20798,0.05242,11.14012,0.06176,0.00247
12.64800,0.53545,1089.45385,0.05270,11.27723,0.06164,0.00247
12.71600,0.53812,1102.70429,0.05297,11.41439,0.06168,0.00247
12.78400,0.54129,1118.33744,0.05328,11.57621,0.06166,0.00247
12.85200,0.54407,1132.16165,0.05355,11.71931,0.06140,0.00246
12.92000,0.54696,1146.87413,0.05384,11.87160,0.06150,0.00246
12.98800,0.54986,1160.23678,0.05412,12.00992,0.06138,0.00246
13.05600,0.55275,1177.32424,0.05440,12.18680,0.06153,0.00246
13.12400,0.55564,1191.03424,0.05469,12.32872,0.06165,0.00247
13.19200,0.55837,1205.71196,0.05496,12.48065,0.06153,0.00246
13.26000,0.56143,1221.23200,0.05526,12.64130,0.06173,0.00247
13.32800,0.56421,1236.18800,0.05553,12.79612,0.06153,0.00246
13.39600,0.56711,1251.30527,0.05582,12.95260,0.06142,0.00246
13.46400,0.56995,1265.02085,0.05610,13.09457,0.06175,0.00247
13.53200,0.57289,1282.14106,0.05639,13.27179,0.06167,0.00247
13.60000,0.57579,1295.50528,0.05667,13.41013,0.06167,0.00247
13.66800,0.57852,1310.43859,0.05694,13.56470,0.06170,0.00247
13.73600,0.58157,1325.71243,0.05724,13.72281,0.06145,0.00246
13.80400,0.58436,1340.87607,0.05752,13.87977,0.06136,0.00245
13.87200,0.58725,1355.24746,0.05780,14.02853,0.06130,0.00245
13.94000,0.59004,1368.62263,0.05807,14.16698,0.06137,0.00245
14.00800,0.59309,1386.14617,0.05837,14.34837,0.06140,0.00246
14.07600,0.59593,1399.53475,0.05865,14.48696,0.06142,0.00246
14.14400,0.59866,1414.12418,0.05892,14.63798,0.06162,0.00246
14.21200,0.60171,1428.60476,0.05922,14.78787,0.06154,0.00246
14.28000,0.60450,1443.92230,0.05950,14.94643,0.06142,0.00246
14.34800,0.60739,1457.70907,0.05978,15.08914,0.06149,0.00246
14.41600,0.61018,1470.88889,0.06006,15.22557,0.06151,0.00246
14.48400,0.61323,1487.20153,0.06036,15.39443,0.06151,0.00246
14.55200,0.61602,1500.09099,0.06063,15.52785,0.06154,0.00246
14.62000,0.61886,1514.59269,0.06091,15.67796,0.06173,0.00247
14.68800,0.62180,1527.86348,0.06120,15.81533,0.06187,0.00247
14.75600,0.62464,1543.38218,0.06148,15.97597,0.06174,0.00247
14.82400,0.62759,1556.80429,0.06177,16.11490,0.06171,0.00247
14.89200,0.63027,1569.63263,0.06203,16.24769,0.06159,0.00246
14.96000,0.63337,1585.55891,0.06234,16.41255,0.06146,0.00246
15.02800,0.63616,1598.11534,0.06261,16.54252,0.06155,0.00246
15.09600,0.63905,1612.43565,0.06290,16.69076,0.06155,0.00246
15.16400,0.64195,1624.90591,0.06318,16.81984,0.06147,0.00246
15.23200,0.64484,1640.70647,0.06347,16.98340,0.06148,0.00246
15.30000,0.64773,1653.23708,0.06375,17.11310,0.06142,0.00246
15.36800,0.65046,1666.58331,0.06402,17.25125,0.06155,0.00246
15.43600,0.65357,1681.44979,0.06433,17.40514,0.06141,0.00246
15.50400,0.65636,1693.87132,0.06460,17.53372,0.06155,0.00246
15.57200,0.65925,1707.34182,0.06489,17.67316,0.06147,0.00246
15.64000,0.66209,1718.87062,0.06517,17.79249,0.06141,0.00246
15.70800,0.66498,1734.53741,0.06545,17.95467,0.06154,0.00246
15.77600,0.66787,1746.32873,0.06574,18.07672,0.06158,0.00246
15.84400,0.67061,1759.43177,0.06600,18.21235,0.06153,0.00246
15.91200,0.67366,1773.17541,0.06631,18.35462,0.06159,0.00246
15.98000,0.67645,1785.52195,0.06658,18.48242,0.06154,0.00246
16.04800,0.67939,1798.54844,0.06687,18.61726,0.06143,0.00246
16.11600,0.68218,1809.92804,0.06714,18.73505,0.06158,0.00246
16.18400,0.68518,1825.38025,0.06744,18.89500,0.06177,0.00247
16.25200,0.68802,1836.10741,0.06772,19.00604,0.06181,0.00247
16.32000,0.69080,1849.51533,0.06799,19.14483,0.06157,0.00246
16.38800,0.69380,1861.98514,0.06829,19.27391,0.06160,0.00246
16.45600,0.69659,1874.75570,0.06856,19.40610,0.06156,0.00246
16.52400,0.69954,1887.11844,0.06885,19.53407,0.06141,0.00246
16.59200,0.70232,1898.56768,0.06913,19.65259,0.06146,0.00246
16.66000,0.70532,1912.77444,0.06942,19.79965,0.06160,0.00246
16.72800,0.70816,1923.82582,0.06970,19.91404,0.06154,0.00246
16.79600,0.71095,1936.91075,0.06997,20.04949,0.06164,0.00247
16.86400,0.71395,1948.84948,0.07027,20.17307,0.06151,0.00246
16.93200,0.71679,1961.55578,0.07055,20.30459,0.06153,0.00246
17.00000,0.71968,1973.32330,0.07083,20.42640,0.06137,0.00245
17.06800,0.72241,1984.41289,0.07110,20.54119,0.06133,0.00245
17.13600,0.72546,1999.32441,0.07140,20.69555,0.06143,0.00246
17.20400,0.72836,2010.23631,0.07169,20.80850,0.06149,0.00246
17.27200,0.73114,2022.69539,0.07196,20.93747,0.06156,0.00246
17.34000,0.73409,2034.00269,0.07225,21.05451,0.06153,0.00246
17.40800,0.73698,2047.48772,0.07254,21.19410,0.06166,0.00247
17.47600,0.73982,2058.75859,0.07282,21.31077,0.06138,0.00246
17.54400,0.74255,2069.81532,0.07309,21.42522,0.06180,0.00247
17.61200,0.74566,2083.62177,0.07339,21.56813,0.06121,0.00245
17.68000,0.74845,2094.21918,0.07367,21.67783,0.06196,0.00248
17.74800,0.75129,2106.43262,0.07395,21.80425,0.06137,0.00245
17.81600,0.75423,2117.39704,0.07424,21.91775,0.06188,0.00248
17.88400,0.75712,2130.95404,0.07452,22.05808,0.06180,0.00247
17.95200,0.75996,2141.55950,0.07480,22.16786,0.06154,0.00246
18.02000,0.76275,2152.52437,0.07507,22.28136,0.06168,0.00247
18.08800,0.76586,2165.80242,0.07538,22.41881,0.06133,0.00245
18.15600,0.76864,2176.60837,0.07565,22.53066,0.06146,0.00246
18.22400,0.77148,2188.72413,0.07593,22.65608,0.06153,0.00246
18.29200,0.77437,2198.85930,0.07622,22.76099,0.06152,0.00246
18.36000,0.77727,2212.55131,0.07650,22.90272,0.06169,0.00247
18.42800,0.78016,2222.61451,0.07679,23.00688,0.06158,0.00246
18.49600,0.78289,2233.59056,0.07706,23.12050,0.06153,0.00246
18.56400,0.78600,2246.51188,0.07736,23.25425,0.06136,0.00245
18.63200,0.78879,2257.43204,0.07764,23.36729,0.06118,0.00245
18.70000,0.79168,2268.96979,0.07792,23.48672,0.06122,0.00245
18.76800,0.79446,2279.10317,0.07820,23.59161,0.06159,0.00246
18.83600,0.79746,2293.19729,0.07849,23.73751,0.06126,0.00245
18.90400,0.80030,2303.54369,0.07877,23.84460,0.06133,0.00245
18.97200,0.80298,2314.86484,0.07903,23.96179,0.06162,0.00246
19.04000,0.80609,2326.96943,0.07934,24.08709,0.06168,0.00247
19.10800,0.80893,2338.94996,0.07962,24.21110,0.06155,0.00246
19.17600,0.81182,2350.35114,0.07990,24.32912,0.06147,0.00246
19.24400,0.81455,2360.21586,0.08017,24.43123,0.06172,0.00247
19.31200,0.81761,2374.51918,0.08047,24.57929,0.06134,0.00245
19.38000,0.82045,2385.04507,0.08075,24.68825,0.06162,0.00246
19.44800,0.82323,2396.75961,0.08103,24.80951,0.06164,0.00247
19.51600,0.82623,2408.00209,0.08132,24.92588,0.06149,0.00246
19.58400,0.82907,2420.88854,0.08160,25.05927,0.06168,0.00247
19.65200,0.83196,2432.28167,0.08189,25.17721,0.06168,0.00247
19.72000,0.83470,2442.65288,0.08216,25.28456,0.06149,0.00246
19.78800,0.83780,2456.73627,0.08246,25.43034,0.06146,0.00246
19.85600,0.84059,2467.08959,0.08274,25.53751,0.06180,0.00247
19.92400,0.84337,2478.90115,0.08301,25.65978,0.06189,0.00248
19.99200,0.84637,2490.37541,0.08330,25.77855,0.06146,0.00246
20.06000,0.84921,2503.63871,0.08358,25.91584,0.06127,0.00245
20.12800,0.85211,2514.56045,0.08387,26.02890,0.06127,0.00245
20.19600,0.85484,2525.30716,0.08414,26.14014,0.06099,0.00244
20.26400,0.85789,2539.43570,0.08444,26.28639,0.06161,0.00246
20.33200,0.86073,2550.15828,0.08472,26.39738,0.06188,0.00248
20.40000,0.86357,2563.20633,0.08500,26.53244,0.06159,0.00246
20.46800,0.86646,2574.25569,0.08528,26.64682,0.06156,0.00246
20.53600,0.86936,2588.55164,0.08557,26.79480,0.06167,0.00247
20.60400,0.87230,2599.51897,0.08586,26.90832,0.06159,0.00246
20.67200,0.87504,2611.26347,0.08613,27.02989,0.06147,0.00246
20.74000,0.87809,2625.23420,0.08643,27.17451,0.06146,0.00246
20.80800,0.88087,2636.54754,0.08670,27.29162,0.06138,0.00246
20.87600,0.88377,2649.03925,0.08698,27.42092,0.06140,0.00246
20.94400,0.88661,2660.08213,0.08726,27.53523,0.06152,0.00246
21.01200,0.88955,2675.41431,0.08755,27.69394,0.06187,0.00247
21.08000,0.89239,2686.75178,0.08783,27.81129,0.06182,0.00247
21.14800,0.89518,2698.69544,0.08811,27.93493,0.06170,0.00247
21.21600,0.89823,2711.79244,0.08841,28.07050,0.06154,0.00246
21.28400,0.90096,2724.45671,0.08868,28.20159,0.06146,0.00246
21.35200,0.90391,2737.39167,0.08897,28.33548,0.06135,0.00245
21.42000,0.90675,2748.91533,0.08925,28.45477,0.06125,0.00245
21.48800,0.90970,2764.11407,0.08954,28.61209,0.06149,0.00246
21.55600,0.91254,2775.22199,0.08982,28.72707,0.06167,0.00247
21.62400,0.91532,2788.01322,0.09009,28.85948,0.06158,0.00246
21.69200,0.91837,2801.85588,0.09039,29.00277,0.06150,0.00246
21.76000,0.92116,2815.10711,0.09067,29.13993,0.06138,0.00246
21.82800,0.92411,2828.06307,0.09096,29.27405,0.06109,0.00244
21.89600,0.92684,2839.83596,0.09122,29.39591,0.06138,0.00246
21.96400,0.92989,2855.94687,0.09152,29.56268,0.06152,0.00246
22.03200,0.93268,2867.55569,0.09180,29.68284,0.06129,0.00245
22.10000,0.93546,2880.75618,0.09207,29.81949,0.06151,0.00246
22.16800,0.93852,2893.87845,0.09237,29.95532,0.06156,0.00246
22.23600,0.94136,2908.32683,0.09265,30.10488,0.06116,0.00245
22.30400,0.94420,2921.14154,0.09293,30.23753,0.06124,0.00245
22.37200,0.94698,2933.76423,0.09321,30.36819,0.06221,0.00249
22.44000,0.95004,2949.81815,0.09351,30.53437,0.06237,0.00249
22.50800,0.95282,2961.65563,0.09378,30.65690,0.06187,0.00247
22.57600,0.95566,2975.35099,0.09406,30.79866,0.06173,0.00247
22.64400,0.95866,2988.52399,0.09436,30.93502,0.06146,0.00246
22.71200,0.96150,3004.17222,0.09464,31.09700,0.06088,0.00244
22.78000,0.96434,3016.94378,0.09492,31.22920,0.06138,0.00246
22.84800,0.96712,3029.35570,0.09519,31.35768,0.06181,0.00247
22.91600,0.97023,3045.73976,0.09550,31.52728,0.06154,0.00246
22.98400,0.97296,3058.23885,0.09576,31.65666,0.06164,0.00247
23.05200,0.97586,3072.22456,0.09605,31.80143,0.06161,0.00246
23.12000,0.97880,3085.07413,0.09634,31.93444,0.06140,0.00246
23.18800,0.98164,3101.65644,0.09662,32.10608,0.06121,0.00245
23.25600,0.98454,3114.54557,0.09690,32.23950,0.06134,0.00245
23.32400,0.98727,3127.85782,0.09717,32.37730,0.06156,0.00246
23.39200,0.99032,3143.83551,0.09747,32.54269,0.06139,0.00246
23.46000,0.99316,3156.81316,0.09775,32.67703,0.06135,0.00245
23.52800,0.99600,3171.53089,0.09803,32.82937,0.06151,0.00246
23.59600,0.99889,3184.75641,0.09832,32.96627,0.06138,0.00246
23.66400,1.00184,3201.49831,0.09861,33.13957,0.06145,0.00246
23.73200,1.00473,3214.24574,0.09889,33.27153,0.06166,0.00247
23.80000,1.00741,3227.96434,0.09915,33.41353,0.06160,0.00246
23.86800,1.01052,3243.40917,0.09946,33.57341,0.06174,0.00247
23.93600,1.01330,3257.69439,0.09973,33.72128,0.06168,0.00247
24.00400,1.01614,3271.89982,0.10001,33.86832,0.06168,0.00247
24.07200,1.01898,3284.60611,0.10029,33.99985,0.06146,0.00246
24.14000,1.02198,3302.29238,0.10059,34.18292,0.06114,0.00245
24.20800,1.02482,3315.22353,0.10087,34.31678,0.06130,0.00245
24.27600,1.02755,3329.56418,0.10114,34.46522,0.06139,0.00246
24.34400,1.03061,3344.96722,0.10144,34.62466,0.06158,0.00246
24.41200,1.03345,3360.42859,0.10172,34.78470,0.06145,0.00246
24.48000,1.03634,3375.01891,0.10200,34.93573,0.06143,0.00246
24.54800,1.03912,3387.66687,0.10228,35.06666,0.06167,0.00247
24.61600,1.04212,3405.41482,0.10257,35.25037,0.06159,0.00246
24.68400,1.04496,3418.97272,0.10285,35.39071,0.06141,0.00246
24.75200,1.04775,3433.66228,0.10312,35.54277,0.06159,0.00246
24.82000,1.05080,3448.33709,0.10343,35.69467,0.06147,0.00246
24.88800,1.05359,3464.61587,0.10370,35.86318,0.06139,0.00246
24.95600,1.05648,3479.12773,0.10398,36.01339,0.06144,0.00246
25.02400,1.05927,3492.85752,0.10426,36.15551,0.06129,0.00245
25.09200,1.06232,3510.24874,0.10456,36.33553,0.06153,0.00246
25.16000,1.06511,3523.91012,0.10483,36.47695,0.06165,0.00247
25.22800,1.06789,3539.44793,0.10511,36.63778,0.06185,0.00247
25.29600,1.07089,3554.02909,0.10540,36.78872,0.06180,0.00247
25.36400,1.07373,3570.82017,0.10568,36.96252,0.06142,0.00246
25.43200,1.07662,3585.53007,0.10597,37.11479,0.06129,0.00245
25.50000,1.07936,3599.52204,0.10624,37.25963,0.06123,0.00245
25.56800,1.08246,3617.15600,0.10654,37.44216,0.06151,0.00246
25.63600,1.08525,3631.31426,0.10682,37.58872,0.06165,0.00247
25.70400,1.08809,3647.49335,0.10710,37.75619,0.06139,0.00246
25.77200,1.09104,3661.66815,0.10739,37.90292,0.06127,0.00245
25.84000,1.09393,3679.78714,0.10767,38.09047,0.06131,0.00245
25.90800,1.09682,3694.03526,0.10795,38.23796,0.06116,0.00245
25.97600,1.09955,3708.81200,0.10822,38.39092,0.06161,0.00246
26.04400,1.10261,3725.75037,0.10852,38.56625,0.06166,0.00247
26.11200,1.10545,3740.98353,0.10880,38.72393,0.06157,0.00246
26.18000,1.10828,3756.70105,0.10908,38.88663,0.06156,0.00246
26.24800,1.11118,3770.92972,0.10937,39.03391,0.06157,0.00246
26.31600,1.11407,3789.33102,0.10965,39.22439,0.06163,0.00247
26.38400,1.11691,3803.48504,0.10993,39.37090,0.06139,0.00246
26.45200,1.11970,3819.02084,0.11021,39.53172,0.06160,0.00246
26.52000,1.12275,3835.74754,0.11051,39.70486,0.06154,0.00246
26.58800,1.12548,3851.84839,0.11078,39.87152,0.06142,0.00246
26.65600,1.12843,3867.55586,0.11107,40.03412,0.06163,0.00247
26.72400,1.13127,3881.91059,0.11135,40.18271,0.06162,0.00246
26.79200,1.13421,3900.67175,0.11164,40.37691,0.06144,0.00246
26.86000,1.13711,3915.43195,0.11192,40.52969,0.06144,0.00246
26.92800,1.13984,3931.61595,0.11219,40.69722,0.06163,0.00247
26.99600,1.14295,3948.29258,0.11249,40.86984,0.06150,0.00246
27.06400,1.14573,3964.58924,0.11277,41.03854,0.06137,0.00245
27.13200,1.14862,3980.30162,0.11305,41.20118,0.06146,0.00246
27.20000,1.15141,3995.06718,0.11333,41.35402,0.06132,0.00245
27.26800,1.15441,4013.82565,0.11362,41.54819,0.06115,0.00245
27.33600,1.15725,4028.87464,0.11390,41.70397,0.06127,0.00245
27.40400,1.16003,4045.54859,0.11418,41.87657,0.06144,0.00246
27.47200,1.16303,4061.31819,0.11447,42.03980,0.06164,0.00247
27.54000,1.16587,4078.49103,0.11475,42.21756,0.06155,0.00246
27.60800,1.16877,4094.30221,0.11504,42.38123,0.06138,0.00246
27.67600,1.17150,4109.56219,0.11531,42.53919,0.06149,0.00246
27.74400,1.17461,4128.67606,0.11561,42.73704,0.06133,0.00245
27.81200,1.17739,4143.41837,0.11589,42.88964,0.06149,0.00246
27.88000,1.18018,4160.13256,0.11616,43.06266,0.06178,0.00247
27.94800,1.18318,4175.91691,0.11645,43.22604,0.06167,0.00247
28.01600,1.18602,4194.50104,0.11673,43.41841,0.06163,0.00247
28.08400,1.18891,4210.07037,0.11702,43.57958,0.06171,0.00247
28.15200,1.19164,4225.49218,0.11729,43.73921,0.06146,0.00246
28.22000,1.19475,4244.27390,0.11759,43.93363,0.06147,0.00246
28.28800,1.19753,4259.40961,0.11787,44.09030,0.06145,0.00246
28.35600,1.20037,4276.34731,0.11815,44.26563,0.06166,0.00247
28.42400,1.20332,4292.09277,0.11844,44.42861,0.06167,0.00247
28.49200,1.20616,4311.15881,0.11872,44.62597,0.06139,0.00246
28.56000,1.20905,4326.52473,0.11900,44.78503,0.06144,0.00246
28.62800,1.21178,4342.24918,0.11927,44.94780,0.06149,0.00246
28.69600,1.21489,4361.17575,0.11958,45.14371,0.06162,0.00246
28.76400,1.21768,4377.33293,0.11985,45.31096,0.06162,0.00246
28.83200,1.22052,4394.18837,0.12013,45.48543,0.06152,0.00246
28.90000,1.22341,4409.48099,0.12041,45.64373,0.06156,0.00246
28.96800,1.22636,4429.33470,0.12070,45.84924,0.06145,0.00246
29.03600,1.22920,4444.92280,0.12098,46.01060,0.06128,0.00245
29.10400,1.23193,4461.11128,0.12125,46.17817,0.06154,0.00246
29.17200,1.23503,4479.68960,0.12156,46.37048,0.06147,0.00246
29.24000,1.23782,4496.35550,0.12183,46.54299,0.06151,0.00246
29.30800,1.24071,4513.28829,0.12212,46.71827,0.06171,0.00247
29.37600,1.24355,4528.59923,0.12240,46.87676,0.06173,0.00247
29.44400,1.24650,4549.29024,0.12269,47.09093,0.06156,0.00246
29.51200,1.24939,4564.59671,0.12297,47.24937,0.06151,0.00246
29.58000,1.25212,4581.52324,0.12324,47.42459,0.06154,0.00246
29.64800,1.25518,4599.08634,0.12354,47.60639,0.06160,0.00246
29.71600,1.25796,4616.63067,0.12382,47.78799,0.06138,0.00246
29.78400,1.26086,4633.44678,0.12410,47.96206,0.06150,0.00246
29.85200,1.26364,4648.95844,0.12437,48.12263,0.06155,0.00246
29.92000,1.26664,4669.76792,0.12467,48.33803,0.06139,0.00246
29.98800,1.26953,4685.70828,0.12495,48.50303,0.06168,0.00247
30.05600,1.27232,4702.61738,0.12523,48.67806,0.06161,0.00246
30.12400,1.27532,4719.98960,0.12552,48.85789,0.06134,0.00245
30.19200,1.27811,4738.16380,0.12580,49.04601,0.06148,0.00246
30.26000,1.28100,4754.89095,0.12608,49.21916,0.06134,0.00245
30.32800,1.28378,4770.55371,0.12636,49.38129,0.06129,0.00245
30.39600,1.28678,4790.95280,0.12665,49.59245,0.06136,0.00245
30.46400,1.28962,4806.87305,0.12693,49.75724,0.06139,0.00246
30.53200,1.29246,4824.71198,0.12721,49.94190,0.06149,0.00246
30.60000,1.29546,4841.38682,0.12751,50.11450,0.06149,0.00246
30.66800,1.29825,4861.14129,0.12778,50.31899,0.06161,0.00246
30.73600,1.30120,4877.38118,0.12807,50.48709,0.06160,0.00246
30.80400,1.30393,4893.67515,0.12834,50.65575,0.06155,0.00246
30.87200,1.30698,4913.69560,0.12864,50.86299,0.06163,0.00247
30.94000,1.30977,4930.02892,0.12891,51.03206,0.06168,0.00247
31.00800,1.31261,4948.38238,0.12919,51.22204,0.06164,0.00247
31.07600,1.31561,4964.84667,0.12949,51.39247,0.06164,0.00247
31.14400,1.31845,4984.97307,0.12977,51.60080,0.06145,0.00246
31.21200,1.32134,5001.22726,0.13005,51.76906,0.06156,0.00246
31.28000,1.32407,5018.37775,0.13032,51.94658,0.06149,0.00246
31.34800,1.32718,5038.33696,0.13063,52.15319,0.06147,0.00246
31.41600,1.32991,5054.74940,0.13090,52.32308,0.06158,0.00246
31.48400,1.33280,5072.57089,0.13118,52.50755,0.06149,0.00246
31.55200,1.33570,5089.13666,0.13147,52.67903,0.06140,0.00246
31.62000,1.33859,5109.73334,0.13175,52.89223,0.06147,0.00246
31.68800,1.34143,5125.92718,0.13203,53.05986,0.06144,0.00246
31.75600,1.34421,5143.69726,0.13230,53.24380,0.06144,0.00246
31.82400,1.34727,5162.74184,0.13261,53.44094,0.06141,0.00246
31.89200,1.35005,5181.00411,0.13288,53.62997,0.06143,0.00246
31.96000,1.35295,5198.89310,0.13316,53.81515,0.06149,0.00246
32.02800,1.35578,5215.06235,0.13344,53.98252,0.06156,0.00246
32.09600,1.35878,5236.37921,0.13374,54.20318,0.06150,0.00246
32.16400,1.36162,5252.53907,0.13402,54.37045,0.06162,0.00246
32.23200,1.36436,5270.40392,0.13429,54.55538,0.06167,0.00247
32.30000,1.36746,5289.23616,0.13459,54.75031,0.06171,0.00247
32.36800,1.37025,5307.84577,0.13487,54.94295,0.06163,0.00247
32.43600,1.37314,5325.25107,0.13515,55.12311,0.06154,0.00246
32.50400,1.37593,5342.27863,0.13543,55.29937,0.06156,0.00246
32.57200,1.37893,5363.25976,0.13572,55.51655,0.06157,0.00246
32.64000,1.38177,5380.24753,0.13600,55.69240,0.06157,0.00246
32.70800,1.38455,5398.27108,0.13627,55.87896,0.06141,0.00246
32.77600,1.38761,5416.42249,0.13658,56.06685,0.06134,0.00245
32.84400,1.39034,5435.53501,0.13684,56.26469,0.06133,0.00245
32.91200,1.39323,5453.40791,0.13713,56.44970,0.06132,0.00245
32.98000,1.39602,5470.45782,0.13740,56.62619,0.06164,0.00247
33.04800,1.39912,5491.86543,0.13771,56.84778,0.06166,0.00247
33.11600,1.40191,5508.41331,0.13798,57.01908,0.06114,0.00245
33.18400,1.40470,5527.38950,0.13826,57.21550,0.06123,0.00245
33.25200,1.40775,5545.29414,0.13856,57.40084,0.06127,0.00245
33.32000,1.41053,5565.87383,0.13883,57.61386,0.06127,0.00245
33.38800,1.41348,5582.96666,0.13912,57.79080,0.06166,0.00247
33.45600,1.41616,5599.89855,0.13939,57.96606,0.06177,0.00247
33.52400,1.41927,5621.15416,0.13969,58.18609,0.06161,0.00246
33.59200,1.42205,5638.58315,0.13997,58.36650,0.06142,0.00246
33.66000,1.42489,5657.38320,0.14025,58.56110,0.06140,0.00246
33.72800,1.42784,5674.45144,0.14054,58.73778,0.06161,0.00246
33.79600,1.43073,5695.65564,0.14082,58.95727,0.06159,0.00246
33.86400,1.43362,5713.54017,0.14110,59.14240,0.06165,0.00247
33.93200,1.43630,5730.98436,0.14137,59.32297,0.06170,0.00247
34.00000,1.43941,5751.28153,0.14167,59.53307,0.06168,0.00247
34.06800,1.44220,5769.18572,0.14195,59.71840,0.06162,0.00246
34.13600,1.44503,5788.26070,0.14223,59.91585,0.06131,0.00245
34.20400,1.44793,5805.12330,0.14251,60.09040,0.06135,0.00245
34.27200,1.45087,5826.68737,0.14280,60.31362,0.06137,0.00245
34.34000,1.45377,5844.36134,0.14309,60.49656,0.06134,0.00245
34.40800,1.45645,5862.10415,0.14335,60.68022,0.06136,0.00245
34.47600,1.45955,5882.53990,0.14366,60.89176,0.06128,0.00245
34.54400,1.46234,5901.12761,0.14393,61.08417,0.06149,0.00246
34.61200,1.46523,5919.83914,0.14422,61.27786,0.06145,0.00246
34.68000,1.46807,5936.56808,0.14450,61.45102,0.06147,0.00246
34.74800,1.47107,5958.38472,0.14479,61.67685,0.06161,0.00246
34.81600,1.47391,5976.44091,0.14507,61.86376,0.06143,0.00246
34.88400,1.47664,5994.51274,0.14534,62.05082,0.06143,0.00246
34.95200,1.47970,6014.17959,0.14564,62.25440,0.06164,0.00247
35.02000,1.48248,6033.64304,0.14591,62.45587,0.06167,0.00247
35.08800,1.48537,6052.45426,0.14620,62.65059,0.06160,0.00246
35.15600,1.48821,6069.91723,0.14648,62.83135,0.06148,0.00246
35.22400,1.49116,6091.96007,0.14677,63.05953,0.06159,0.00246
35.29200,1.49405,6109.56341,0.14705,63.24174,0.06162,0.00246
35.36000,1.49678,6129.08900,0.14732,63.44386,0.06156,0.00246
35.42800,1.49984,6147.91542,0.14762,63.63873,0.06155,0.00246
35.49600,1.50262,6168.12810,0.14790,63.84796,0.06145,0.00246
35.56400,1.50557,6186.69212,0.14819,64.04012,0.06140,0.00246
35.63200,1.50836,6204.49439,0.14846,64.22440,0.06149,0.00246
35.70000,1.51141,6226.62351,0.14876,64.45346,0.06143,0.00246
35.76800,1.51420,6244.18795,0.14903,64.63528,0.06151,0.00246
35.83600,1.51698,6263.33356,0.14931,64.83346,0.06132,0.00245
35.90400,1.51998,6282.08846,0.14960,65.02760,0.06133,0.00245
35.97200,1.52277,6302.83266,0.14988,65.24232,0.06132,0.00245
36.04000,1.52571,6321.48027,0.15017,65.43535,0.06133,0.00245
36.10800,1.52845,6339.13770,0.15044,65.61813,0.06153,0.00246
36.17600,1.53155,6360.87656,0.15074,65.84315,0.06172,0.00247
36.24400,1.53434,6379.21438,0.15102,66.03297,0.06180,0.00247
36.31200,1.53718,6399.28088,0.15130,66.24069,0.06171,0.00247
36.38000,1.54012,6417.06213,0.15159,66.42475,0.06146,0.00246
36.44800,1.54296,6438.52383,0.15187,66.64690,0.06138,0.00246
36.51600,1.54586,6456.88131,0.15215,66.83692,0.06148,0.00246
36.58400,1.54859,6475.53250,0.15242,67.02999,0.06167,0.00247
36.65200,1.55170,6496.84712,0.15273,67.25062,0.06184,0.00247
36.72000,1.55443,6515.11878,0.15299,67.43976,0.06168,0.00247
36.78800,1.55732,6534.58402,0.15328,67.64125,0.06165,0.00247
36.85600,1.56021,6552.94955,0.15356,67.83135,0.06162,0.00246
36.92400,1.56311,6575.72731,0.15385,68.06713,0.06136,0.00245
36.99200,1.56600,6593.72315,0.15413,68.25341,0.06146,0.00246
37.06000,1.56873,6612.42798,0.15440,68.44703,0.06142,0.00246
37.12800,1.57184,6633.48913,0.15471,68.66504,0.06139,0.00246
37.19600,1.57462,6653.01338,0.15498,68.86714,0.06140,0.00246
37.26400,1.57746,6672.59708,0.15526,69.06986,0.06131,0.00245
37.33200,1.58036,6690.54329,0.15555,69.25562,0.06148,0.00246
37.40000,1.58330,6713.69299,0.15584,69.49525,0.06130,0.00245
37.46800,1.58614,6731.83858,0.15612,69.68308,0.06145,0.00246
37.53600,1.58893,6751.16703,0.15639,69.88316,0.06153,0.00246
37.60400,1.59203,6771.39312,0.15670,70.09252,0.06162,0.00246
37.67200,1.59477,6791.78327,0.15697,70.30358,0.06155,0.00246
37.74000,1.59766,6811.24359,0.15725,70.50502,0.06141,0.00246
37.80800,1.60050,6829.24882,0.15753,70.69140,0.06142,0.00246
37.87600,1.60345,6852.12493,0.15782,70.92820,0.06161,0.00246
37.94400,1.60628,6870.08142,0.15810,71.11407,0.06169,0.00247
38.01200,1.60902,6890.07372,0.15837,71.32102,0.06167,0.00247
38.08000,1.61212,6910.22739,0.15867,71.52963,0.06164,0.00247
38.14800,1.61486,6931.20003,0.15894,71.74673,0.06144,0.00246
38.21600,1.61780,6950.54591,0.15923,71.94698,0.06145,0.00246
38.28400,1.62059,6968.99951,0.15951,72.13800,0.06162,0.00246
38.35200,1.62364,6991.75626,0.15981,72.37356,0.06155,0.00246
38.42000,1.62648,7010.57956,0.16009,72.56840,0.06141,0.00246
38.48800,1.62927,7030.45115,0.16036,72.77410,0.06136,0.00245
38.55600,1.63227,7050.17835,0.16066,72.97830,0.06149,0.00246
38.62400,1.63511,7071.80142,0.16094,73.20213,0.06146,0.00246
38.69200,1.63800,7091.07935,0.16122,73.40168,0.06133,0.00245
38.76000,1.64073,7109.00277,0.16149,73.58721,0.06143,0.00246
38.82800,1.64378,7132.47344,0.16179,73.83016,0.06138,0.00246
38.89600,1.64662,7151.05981,0.16207,74.02255,0.06149,0.00246
38.96400,1.64941,7170.91173,0.16234,74.22805,0.06151,0.00246
39.03200,1.65236,7189.78330,0.16263,74.42339,0.06155,0.00246
39.10000,1.65525,7212.68892,0.16292,74.66049,0.06154,0.00246
39.16800,1.65814,7231.76301,0.16320,74.85793,0.06165,0.00247
39.23600,1.66082,7250.83977,0.16347,75.05540,0.06153,0.00246
39.30400,1.66393,7273.31623,0.16377,75.28806,0.06157,0.00246
39.37200,1.66671,7292.51817,0.16405,75.48683,0.06156,0.00246
39.44000,1.66955,7313.51987,0.16433,75.70422,0.06140,0.00246
39.50800,1.67250,7331.99000,0.16462,75.89541,0.06142,0.00246
39.57600,1.67539,7354.84868,0.16490,76.13203,0.06166,0.00247
39.64400,1.67828,7374.17445,0.16519,76.33207,0.06180,0.00247
39.71200,1.68102,7393.48233,0.16545,76.53193,0.06186,0.00247
39.78000,1.68412,7415.26142,0.16576,76.75738,0.06161,0.00246
39.84800,1.68691,7435.39095,0.16603,76.96574,0.06145,0.00246
39.91600,1.68975,7455.94293,0.16631,77.17848,0.06138,0.00246
39.98400,1.69264,7473.92982,0.16660,77.36467,0.06137,0.00245
40.05200,1.69559,7497.50510,0.16689,77.60870,0.06155,0.00246
40.12000,1.69843,7516.73073,0.16717,77.80771,0.06156,0.00246
40.18800,1.70116,7536.13651,0.16744,78.00859,0.06145,0.00246
40.25600,1.70421,7557.40732,0.16774,78.22877,0.06159,0.00246
40.32400,1.70700,7577.96556,0.16801,78.44157,0.06161,0.00246
40.39200,1.70989,7598.22696,0.16830,78.65130,0.06150,0.00246
40.46000,1.71273,7616.89514,0.16858,78.84454,0.06135,0.00245
40.52800,1.71573,7640.63805,0.16887,79.09031,0.06124,0.00245
40.59600,1.71857,7659.51812,0.16915,79.28574,0.06143,0.00246
40.66400,1.72130,7680.24623,0.16942,79.50031,0.06137,0.00245
40.73200,1.72436,7700.36995,0.16972,79.70861,0.06148,0.00246
40.80000,1.72720,7722.00108,0.17000,79.93252,0.06143,0.00246
40.86800,1.73009,7742.44130,0.17028,80.14410,0.06170,0.00247
40.93600,1.73287,7761.29454,0.17056,80.33926,0.06186,0.00247
41.00400,1.73593,7784.38658,0.17086,80.57829,0.06177,0.00247
41.07200,1.73871,7803.12091,0.17113,80.77221,0.06166,0.00247
41.14000,1.74150,7824.60898,0.17141,80.99464,0.06160,0.00246
41.20800,1.74450,7844.44571,0.17170,81.19998,0.06142,0.00246
41.27600,1.74728,7866.82248,0.17198,81.43161,0.06154,0.00246
41.34400,1.75023,7886.77096,0.17227,81.63810,0.06168,0.00247
41.41200,1.75302,7906.45301,0.17254,81.84183,0.06159,0.00246
41.48000,1.75607,7929.57723,0.17284,82.08120,0.06144,0.00246
41.54800,1.75886,7948.84443,0.17312,82.28064,0.06137,0.00245
41.61600,1.76170,7969.88636,0.17340,82.49845,0.06149,0.00246
41.68400,1.76464,7989.38334,0.17369,82.70027,0.06142,0.00246
41.75200,1.76748,8012.60948,0.17396,82.94069,0.06156,0.00246
41.82000,1.77037,8032.07070,0.17425,83.14214,0.06151,0.00246
41.88800,1.77316,8052.05405,0.17452,83.34899,0.06132,0.00245
41.95600,1.77621,8074.92971,0.17482,83.58578,0.06138,0.00246
42.02400,1.77900,8094.87462,0.17510,83.79224,0.06146,0.00246
42.09200,1.78184,8115.88079,0.17538,84.00968,0.06148,0.00246
42.16000,1.78478,8135.24634,0.17567,84.21013,0.06149,0.00246
42.22800,1.78768,8158.83547,0.17595,84.45431,0.06151,0.00246
42.29600,1.79052,8178.27165,0.17623,84.65550,0.06157,0.00246
42.36400,1.79325,8198.52233,0.17650,84.86512,0.06156,0.00246
42.43200,1.79636,8220.88122,0.17681,85.09656,0.06155,0.00246
42.50000,1.79914,8241.74702,0.17708,85.31255,0.06157,0.00246
42.56800,1.80203,8262.81488,0.17737,85.53063,0.06155,0.00246
42.63600,1.80487,8282.09460,0.17765,85.73020,0.06164,0.00247
42.70400,1.80782,8306.32478,0.17794,85.98101,0.06175,0.00247
42.77200,1.81071,8325.89328,0.17822,86.18357,0.06162,0.00246
42.84000,1.81345,8346.45241,0.17849,86.39639,0.06155,0.00246
42.90800,1.81655,8368.16132,0.17879,86.62110,0.06157,0.00246
42.97600,1.81928,8389.63240,0.17906,86.84335,0.06148,0.00246
43.04400,1.82218,8410.30419,0.17935,87.05733,0.06162,0.00246
43.11200,1.82502,8429.93975,0.17963,87.26059,0.06148,0.00246
43.18000,1.82796,8454.45871,0.17992,87.51439,0.06148,0.00246
43.24800,1.83080,8473.72502,0.18020,87.71382,0.06152,0.00246
43.31600,1.83359,8495.20057,0.18047,87.93612,0.06154,0.00246
43.38400,1.83664,8516.81828,0.18077,88.15989,0.06171,0.00247
43.45200,1.83943,8539.12801,0.18105,88.39082,0.06150,0.00246
43.52000,1.84237,8559.75688,0.18134,88.60436,0.06130,0.00245
43.58800,1.84511,8579.01156,0.18160,88.80367,0.06154,0.00246
43.65600,1.84816,8603.55824,0.18191,89.05776,0.06151,0.00246
43.72400,1.85100,8623.31808,0.18218,89.26230,0.06166,0.00247
43.79200,1.85378,8644.46104,0.18246,89.48115,0.06178,0.00247
43.86000,1.85684,8665.39568,0.18276,89.69785,0.06180,0.00247
43.92800,1.85962,8688.51900,0.18303,89.93721,0.06170,0.00247
43.99600,1.86252,8708.74196,0.18332,90.14654,0.06142,0.00246
44.06400,1.86525,8727.99128,0.18359,90.34580,0.06149,0.00246
44.13200,1.86836,8752.26796,0.18389,90.59709,0.06158,0.00246
44.20000,1.87114,8772.07786,0.18417,90.80215,0.06155,0.00246
44.26800,1.87393,8793.34241,0.18444,91.02226,0.06185,0.00247
44.33600,1.87693,8813.60024,0.18474,91.23196,0.06166,0.00247
44.40400,1.87977,8837.37445,0.18502,91.47805,0.06127,0.00245
44.47200,1.88261,8857.97828,0.18530,91.69133,0.06138,0.00246
44.54000,1.88539,8878.05909,0.18557,91.89919,0.06122,0.00245
44.60800,1.88850,8901.86459,0.18588,92.14561,0.06134,0.00245
44.67600,1.89128,8922.82963,0.18615,92.36262,0.06133,0.00245
44.74400,1.89412,8944.44108,0.18643,92.58633,0.06152,0.00246
44.81200,1.89707,8964.00064,0.18672,92.78879,0.06162,0.00246
44.88000,1.89996,8988.60365,0.18700,93.04347,0.06144,0.00246
44.94800,1.90286,9008.47256,0.18729,93.24914,0.06179,0.00247
45.01600,1.90559,9029.17027,0.18756,93.46338,0.06167,0.00247
45.08400,1.90864,9052.20956,0.18786,93.70187,0.06142,0.00246
45.15200,1.91143,9073.24880,0.18813,93.91965,0.06180,0.00247
45.22000,1.91432,9095.16960,0.18842,94.14656,0.06156,0.00246
45.28800,1.91716,9114.59774,0.18870,94.34767,0.06158,0.00246
45.35600,1.92011,9139.18912,0.18899,94.60222,0.06170,0.00247
45.42400,1.92295,9158.99634,0.18927,94.80725,0.06160,0.00246
45.49200,1.92568,9180.68200,0.18954,95.03172,0.06172,0.00247
45.56000,1.92873,9202.70920,0.18984,95.25973,0.06152,0.00246
45.62800,1.93152,9224.38502,0.19011,95.48410,0.06152,0.00246
45.69600,1.93441,9246.36036,0.19039,95.71158,0.06156,0.00246
45.76400,1.93725,9266.42060,0.19067,95.91922,0.06129,0.00245
45.83200,1.94025,9291.16130,0.19097,96.17532,0.06135,0.00245
45.90000,1.94314,9310.83977,0.19125,96.37902,0.06146,0.00246
45.96800,1.94587,9332.48788,0.19152,96.60311,0.06150,0.00246
46.03600,1.94893,9354.28977,0.19182,96.82878,0.06144,0.00246
46.10400,1.95171,9376.77920,0.19210,97.06158,0.06134,0.00245
46.17200,1.95461,9398.01425,0.19238,97.28139,0.06136,0.00245
46.24000,1.95739,9418.06287,0.19266,97.48891,0.06130,0.00245
46.30800,1.96045,9442.68465,0.19296,97.74378,0.06139,0.00246
46.37600,1.96323,9462.46147,0.19323,97.94850,0.06172,0.00247
46.44400,1.96607,9484.61026,0.19351,98.17777,0.06163,0.00247
46.51200,1.96907,9505.66918,0.19381,98.39575,0.06154,0.00246
46.58000,1.97186,9529.02228,0.19408,98.63749,0.06148,0.00246
46.64800,1.97475,9549.71552,0.19437,98.85169,0.06150,0.00246
46.71600,1.97753,9570.40876,0.19464,99.06589,0.06161,0.00246
46.78400,1.98059,9594.87230,0.19494,99.31912,0.06151,0.00246
46.85200,1.98337,9614.96204,0.19521,99.52707,0.06154,0.00246
46.92000,1.98621,9637.38978,0.19549,99.75923,0.06171,0.00247
46.98800,1.98921,9658.34051,0.19579,99.97609,0.06158,0.00246
47.05600,1.99205,9682.42228,0.19607,100.22537,0.06154,0.00246
47.12400,1.99495,9703.09496,0.19635,100.43936,0.06146,0.00246
47.19200,1.99768,9723.65230,0.19662,100.65215,0.06145,0.00246
47.26000,2.00078,9747.98173,0.19693,100.90399,0.06150,0.00246
47.32800,2.00357,9768.73398,0.19720,101.11881,0.06153,0.00246
47.39600,2.00636,9790.71200,0.19748,101.34631,0.06153,0.00246
47.46400,2.00930,9811.14775,0.19777,101.55784,0.06146,0.00246
47.53200,2.01220,9836.32118,0.19805,101.81842,0.06137,0.00245
47.60000,2.01503,9856.61209,0.19833,102.02846,0.06157,0.00246
47.66800,2.01782,9877.65938,0.19860,102.24632,0.06159,0.00246
47.73600,2.02093,9901.50332,0.19891,102.49314,0.06152,0.00246
47.80400,2.02366,9923.09868,0.19918,102.71668,0.06154,0.00246
47.87200,2.02655,9944.91845,0.19946,102.94254,0.06165,0.00247
47.94000,2.02945,9965.10386,0.19975,103.15148,0.06173,0.00247
48.00800,2.03234,9990.91744,0.20003,103.41869,0.06170,0.00247
48.04200,2.03373,10000.42230,0.20017,103.51707,0.06135,0.00245